Workbook

Sheet Loan Amortization
A1: Loan Amortization Schedule – Apex Delivery Ltd.
A2: Electric delivery vans – commercial vehicle loan (BDT)
A4: Inputs
A5: Loan Amount (Principal) | B5: 1200000 | C5: BDT
A6: Annual Interest Rate | B6: 0.105
A7: Loan Tenure (Years) | B7: 4
A8: Payments per Year | B8: 12
A10: Results
A11: Periodic Rate | B11: =B6/B8 -> 0.00875
A12: Number of Payments | B12: =B7*B8 -> 48
A13: Payment per Period (EMI) | B13: =-PMT(B11,B12,B5) -> 30724.056
A14: Total Payments | B14: =B13*B12 -> 1474754.7
A15: Total Interest Paid | B15: =B14-B5 -> 274754.67
A17: Amortization Schedule | I17: Annual Summary
A18: Period | B18: Year | C18: Opening Balance | D18: Payment | E18: Interest | F18: Principal | G18: Closing Balance | I18: Year | J18: Payments | K18: Interest | L18: Principal | M18: Closing Balance
A19: =IF(ROW()-18<=$B$12,ROW()-18,"") -> 1 | B19: =IF(A19="","",ROUNDUP(A19/$B$8,0)) -> 1 | C19: =IF(A19="","",$B$5) -> 1200000 | D19: =IF(A19="","",$B$13) -> 30724.056 | E19: =IF(A19="","",C19*$B$11) -> 10500 | F19: =IF(A19="","",D19-E19) -> 20224.056 | G19: =IF(A19="","",C19-F19) -> 1179775.9 | I19: 1 | J19: =SUMIFS($D$19:$D$66,$B$19:$B$66,I19) -> 368688.67 | K19: =SUMIFS($E$19:$E$66,$B$19:$B$66,I19) -> 113973.16 | L19: =SUMIFS($F$19:$F$66,$B$19:$B$66,I19) -> 254715.51 | M19: =$B$5-SUM($L$19:L19) -> 945284.49
A20: =IF(ROW()-18<=$B$12,ROW()-18,"") -> 2 | B20: =IF(A20="","",ROUNDUP(A20/$B$8,0)) -> 1 | C20: =IF(A20="","",G19) -> 1179775.9 | D20: =IF(A20="","",$B$13) -> 30724.056 | E20: =IF(A20="","",C20*$B$11) -> 10323.04 | F20: =IF(A20="","",D20-E20) -> 20401.016 | G20: =IF(A20="","",C20-F20) -> 1159374.9 | I20: 2 | J20: =SUMIFS($D$19:$D$66,$B$19:$B$66,I20) -> 368688.67 | K20: =SUMIFS($E$19:$E$66,$B$19:$B$66,I20) -> 85902.629 | L20: =SUMIFS($F$19:$F$66,$B$19:$B$66,I20) -> 282786.04 | M20: =$B$5-SUM($L$19:L20) -> 662498.45
A21: =IF(ROW()-18<=$B$12,ROW()-18,"") -> 3 | B21: =IF(A21="","",ROUNDUP(A21/$B$8,0)) -> 1 | C21: =IF(A21="","",G20) -> 1159374.9 | D21: =IF(A21="","",$B$13) -> 30724.056 | E21: =IF(A21="","",C21*$B$11) -> 10144.531 | F21: =IF(A21="","",D21-E21) -> 20579.525 | G21: =IF(A21="","",C21-F21) -> 1138795.4 | I21: 3 | J21: =SUMIFS($D$19:$D$66,$B$19:$B$66,I21) -> 368688.67 | K21: =SUMIFS($E$19:$E$66,$B$19:$B$66,I21) -> 54738.632 | L21: =SUMIFS($F$19:$F$66,$B$19:$B$66,I21) -> 313950.04 | M21: =$B$5-SUM($L$19:L21) -> 348548.41
A22: =IF(ROW()-18<=$B$12,ROW()-18,"") -> 4 | B22: =IF(A22="","",ROUNDUP(A22/$B$8,0)) -> 1 | C22: =IF(A22="","",G21) -> 1138795.4 | D22: =IF(A22="","",$B$13) -> 30724.056 | E22: =IF(A22="","",C22*$B$11) -> 9964.4598 | F22: =IF(A22="","",D22-E22) -> 20759.596 | G22: =IF(A22="","",C22-F22) -> 1118035.8 | I22: 4 | J22: =SUMIFS($D$19:$D$66,$B$19:$B$66,I22) -> 368688.67 | K22: =SUMIFS($E$19:$E$66,$B$19:$B$66,I22) -> 20140.255 | L22: =SUMIFS($F$19:$F$66,$B$19:$B$66,I22) -> 348548.41 | M22: =$B$5-SUM($L$19:L22) -> 0
A23: =IF(ROW()-18<=$B$12,ROW()-18,"") -> 5 | B23: =IF(A23="","",ROUNDUP(A23/$B$8,0)) -> 1 | C23: =IF(A23="","",G22) -> 1118035.8 | D23: =IF(A23="","",$B$13) -> 30724.056 | E23: =IF(A23="","",C23*$B$11) -> 9782.8133 | F23: =IF(A23="","",D23-E23) -> 20941.242 | G23: =IF(A23="","",C23-F23) -> 1097094.6 | I23: Total | J23: =SUM(J19:J22) -> 1474754.7 | K23: =SUM(K19:K22) -> 274754.67 | L23: =SUM(L19:L22) -> 1200000
A24: =IF(ROW()-18<=$B$12,ROW()-18,"") -> 6 | B24: =IF(A24="","",ROUNDUP(A24/$B$8,0)) -> 1 | C24: =IF(A24="","",G23) -> 1097094.6 | D24: =IF(A24="","",$B$13) -> 30724.056 | E24: =IF(A24="","",C24*$B$11) -> 9599.5774 | F24: =IF(A24="","",D24-E24) -> 21124.478 | G24: =IF(A24="","",C24-F24) -> 1075970.1
A25: =IF(ROW()-18<=$B$12,ROW()-18,"") -> 7 | B25: =IF(A25="","",ROUNDUP(A25/$B$8,0)) -> 1 | C25: =IF(A25="","",G24) -> 1075970.1 | D25: =IF(A25="","",$B$13) -> 30724.056 | E25: =IF(A25="","",C25*$B$11) -> 9414.7383 | F25: =IF(A25="","",D25-E25) -> 21309.317 | G25: =IF(A25="","",C25-F25) -> 1054660.8
A26: =IF(ROW()-18<=$B$12,ROW()-18,"") -> 8 | B26: =IF(A26="","",ROUNDUP(A26/$B$8,0)) -> 1 | C26: =IF(A26="","",G25) -> 1054660.8 | D26: =IF(A26="","",$B$13) -> 30724.056 | E26: =IF(A26="","",C26*$B$11) -> 9228.2817 | F26: =IF(A26="","",D26-E26) -> 21495.774 | G26: =IF(A26="","",C26-F26) -> 1033165
A27: =IF(ROW()-18<=$B$12,ROW()-18,"") -> 9 | B27: =IF(A27="","",ROUNDUP(A27/$B$8,0)) -> 1 | C27: =IF(A27="","",G26) -> 1033165 | D27: =IF(A27="","",$B$13) -> 30724.056 | E27: =IF(A27="","",C27*$B$11) -> 9040.1937 | F27: =IF(A27="","",D27-E27) -> 21683.862 | G27: =IF(A27="","",C27-F27) -> 1011481.1
A28: =IF(ROW()-18<=$B$12,ROW()-18,"") -> 10 | B28: =IF(A28="","",ROUNDUP(A28/$B$8,0)) -> 1 | C28: =IF(A28="","",G27) -> 1011481.1 | D28: =IF(A28="","",$B$13) -> 30724.056 | E28: =IF(A28="","",C28*$B$11) -> 8850.4599 | F28: =IF(A28="","",D28-E28) -> 21873.596 | G28: =IF(A28="","",C28-F28) -> 989607.54
A29: =IF(ROW()-18<=$B$12,ROW()-18,"") -> 11 | B29: =IF(A29="","",ROUNDUP(A29/$B$8,0)) -> 1 | C29: =IF(A29="","",G28) -> 989607.54 | D29: =IF(A29="","",$B$13) -> 30724.056 | E29: =IF(A29="","",C29*$B$11) -> 8659.066 | F29: =IF(A29="","",D29-E29) -> 22064.99 | G29: =IF(A29="","",C29-F29) -> 967542.55
A30: =IF(ROW()-18<=$B$12,ROW()-18,"") -> 12 | B30: =IF(A30="","",ROUNDUP(A30/$B$8,0)) -> 1 | C30: =IF(A30="","",G29) -> 967542.55 | D30: =IF(A30="","",$B$13) -> 30724.056 | E30: =IF(A30="","",C30*$B$11) -> 8465.9973 | F30: =IF(A30="","",D30-E30) -> 22258.058 | G30: =IF(A30="","",C30-F30) -> 945284.49
A31: =IF(ROW()-18<=$B$12,ROW()-18,"") -> 13 | B31: =IF(A31="","",ROUNDUP(A31/$B$8,0)) -> 2 | C31: =IF(A31="","",G30) -> 945284.49 | D31: =IF(A31="","",$B$13) -> 30724.056 | E31: =IF(A31="","",C31*$B$11) -> 8271.2393 | F31: =IF(A31="","",D31-E31) -> 22452.816 | G31: =IF(A31="","",C31-F31) -> 922831.67
A32: =IF(ROW()-18<=$B$12,ROW()-18,"") -> 14 | B32: =IF(A32="","",ROUNDUP(A32/$B$8,0)) -> 2 | C32: =IF(A32="","",G31) -> 922831.67 | D32: =IF(A32="","",$B$13) -> 30724.056 | E32: =IF(A32="","",C32*$B$11) -> 8074.7771 | F32: =IF(A32="","",D32-E32) -> 22649.279 | G32: =IF(A32="","",C32-F32) -> 900182.39
A33: =IF(ROW()-18<=$B$12,ROW()-18,"") -> 15 | B33: =IF(A33="","",ROUNDUP(A33/$B$8,0)) -> 2 | C33: =IF(A33="","",G32) -> 900182.39 | D33: =IF(A33="","",$B$13) -> 30724.056 | E33: =IF(A33="","",C33*$B$11) -> 7876.5959 | F33: =IF(A33="","",D33-E33) -> 22847.46 | G33: =IF(A33="","",C33-F33) -> 877334.93
A34: =IF(ROW()-18<=$B$12,ROW()-18,"") -> 16 | B34: =IF(A34="","",ROUNDUP(A34/$B$8,0)) -> 2 | C34: =IF(A34="","",G33) -> 877334.93 | D34: =IF(A34="","",$B$13) -> 30724.056 | E34: =IF(A34="","",C34*$B$11) -> 7676.6807 | F34: =IF(A34="","",D34-E34) -> 23047.375 | G34: =IF(A34="","",C34-F34) -> 854287.56
A35: =IF(ROW()-18<=$B$12,ROW()-18,"") -> 17 | B35: =IF(A35="","",ROUNDUP(A35/$B$8,0)) -> 2 | C35: =IF(A35="","",G34) -> 854287.56 | D35: =IF(A35="","",$B$13) -> 30724.056 | E35: =IF(A35="","",C35*$B$11) -> 7475.0161 | F35: =IF(A35="","",D35-E35) -> 23249.04 | G35: =IF(A35="","",C35-F35) -> 831038.52
... A66: =IF(ROW()-18<=$B$12,ROW()-18,"") -> 48 | B66: =IF(A66="","",ROUNDUP(A66/$B$8,0)) -> 4 | C66: =IF(A66="","",G65) -> 30457.552 | D66: =IF(A66="","",$B$13) -> 30724.056 | E66: =IF(A66="","",C66*$B$11) -> 266.50358 | F66: =IF(A66="","",D66-E66) -> 30457.552 | G66: =IF(A66="","",C66-F66) -> 1.6734703e-10
A67: Total | D67: =SUM(D19:D66) -> 1474754.7 | E67: =SUM(E19:E66) -> 274754.67 | F67: =SUM(F19:F66) -> 1200000
A68: Check: closing balance after last payment (should be 0) | B68: {=ROUND(INDEX(G19:G66,B12),2)} -> 0

Sheet DCF Model
A1: DCF Valuation – Electric Delivery Van Fleet
A2: Apex Delivery Ltd. (BDT)
A4: Inputs
A5: Initial Investment (Year 0 outflow) | B5: 1200000
A6: Discount Rate (Cost of Capital) | B6: 0.11
A8: Cash Flow Schedule | B8: Year 0 | C8: Year 1 | D8: Year 2 | E8: Year 3 | F8: Year 4
A9: Year | B9: 0 | C9: 1 | D9: 2 | E9: 3 | F9: 4
A10: Net Cash Flow | B10: =-B5 -> -1200000 | C10: 400000 | D10: 500000 | E10: 450000 | F10: 350000
A11: Discount Factor | B11: =1/(1+$B$6)^B9 -> 1 | C11: =1/(1+$B$6)^C9 -> 0.9009009 | D11: =1/(1+$B$6)^D9 -> 0.81162243 | E11: =1/(1+$B$6)^E9 -> 0.73119138 | F11: =1/(1+$B$6)^F9 -> 0.65873097
A12: Present Value | B12: =B10*B11 -> -1200000 | C12: =C10*C11 -> 360360.36 | D12: =D10*D11 -> 405811.22 | E12: =E10*E11 -> 329036.12 | F12: =F10*F11 -> 230555.84
A13: Cumulative Cash Flow | B13: =B10 -> -1200000 | C13: =B13+C10 -> -800000 | D13: =C13+D10 -> -300000 | E13: =D13+E10 -> 150000 | F13: =E13+F10 -> 500000
A14: Cumulative Present Value | B14: =B12 -> -1200000 | C14: =B14+C12 -> -839639.64 | D14: =C14+D12 -> -433828.42 | E14: =D14+E12 -> -104792.3 | F14: =E14+F12 -> 125763.54
A15: Payback helper (undiscounted) | B15: 0 | C15: =IF(AND(B13<0,C13>=0),B9-B13/C10,0) -> 0 | D15: =IF(AND(C13<0,D13>=0),C9-C13/D10,0) -> 0 | E15: =IF(AND(D13<0,E13>=0),D9-D13/E10,0) -> 2.6666667 | F15: =IF(AND(E13<0,F13>=0),E9-E13/F10,0) -> 0
A16: Payback helper (discounted) | B16: 0 | C16: =IF(AND(B14<0,C14>=0),B9-B14/C12,0) -> 0 | D16: =IF(AND(C14<0,D14>=0),C9-C14/D12,0) -> 0 | E16: =IF(AND(D14<0,E14>=0),D9-D14/E12,0) -> 0 | F16: =IF(AND(E14<0,F14>=0),E9-E14/F12,0) -> 3.4545203
A18: Results
A19: Sum of PV of Cash Inflows | B19: =SUM(C12:F12) -> 1325763.5
A20: Net Present Value (NPV) | B20: =SUM(B12:F12) -> 125763.54
A21: NPV check (Excel NPV function) | B21: =NPV(B6,C10:F10)+B10 -> 125763.54
A22: Internal Rate of Return (IRR) | B22: =IRR(B10:F10) -> 0.15915305
A23: Profitability Index (PV inflows / investment) | B23: =B19/B5 -> 1.1048029
A24: Payback Period (years) | B24: =IF(SUM(B15:F15)=0,"Not recovered",SUM(B15:F15)) -> 2.6666667
A25: Discounted Payback Period (years) | B25: =IF(SUM(B16:F16)=0,"Not recovered",SUM(B16:F16)) -> 3.4545203
A26: Decision | B26: =IF(B20>0,"ACCEPT – NPV is positive and IRR exceeds the cost of capital","REJECT – NPV is negative") -> ACCEPT – NPV is positive and IRR exceeds the cost of capital

Sheet Dashboard
B2: Financial Health Dashboard
B3: All companies consolidated | fiscal year to date (Apr–Oct)
B5: Closing Cash (Oct) | F5: Total Income (YTD) | J5: Total Expenses (YTD) | N5: Net Profit (YTD)
B6: ='Dashboard Data'!H5 -> 13594797 | F6: ='Dashboard Data'!H6 -> 42076441 | J6: ='Dashboard Data'!H7 -> 38659422 | N6: ='Dashboard Data'!H8 -> 3417018.7
B7: ="Total assets "&TEXT('Dashboard Data'!H11/1000000,"0.00")&"M" -> Total assets 49.12M | F7: ="Oct "&TEXT('Dashboard Data'!I6/1000000,"0.00;-0.00")&"M | Sep "&TEXT('Dashboard Data'!J6/1000000,"0.00;-0.00")&"M" -> Oct 5.54M | Sep 6.95M | J7: ="Oct "&TEXT('Dashboard Data'!I7/1000000,"0.00;-0.00")&"M | Sep "&TEXT('Dashboard Data'!J7/1000000,"0.00;-0.00")&"M" -> Oct 5.73M | Sep 5.65M | N7: ="Oct "&TEXT('Dashboard Data'!I8/1000000,"0.00;-0.00")&"M | Sep "&TEXT('Dashboard Data'!J8/1000000,"0.00;-0.00")&"M" -> Oct -0.19M | Sep 1.29M
B10: Overall Financial Health | F10: Gross Profit Margin | J10: Return on Equity (annualized) | N10: Days Sales Outstanding
B11: =UPPER('Dashboard Data'!H9) -> GOOD | F11: ='Dashboard Data'!H14 -> 0.80446982 | J11: ='Dashboard Data'!H15 -> 0.20351336 | N11: ='Dashboard Data'!H16 -> 144.70413
B12: ="Average ratio score "&TEXT('Dashboard Data'!H10,"0.00")&" / 3" -> Average ratio score 1.67 / 3 | F12: ="Rating: "&'Dashboard Data'!I14 -> Rating: Excellent | J12: ="Rating: "&'Dashboard Data'!I15 -> Rating: Excellent | N12: ="Rating: "&'Dashboard Data'!I16 -> Rating: Bad

Sheet Health Summary
A1: Business Financial Health Summary
A2: Fiscal year to date (Apr–Oct), all companies consolidated
A4: Key figures | B4: Amount
A5: Net sales (YTD) | B5: ='Income Statement'!I8 -> 41709630
A6: Gross profit (YTD) | B6: ='Income Statement'!I13 -> 33554139
A7: Operating profit (YTD) | B7: ='Income Statement'!I27 -> 4356663.1
A8: Net profit (YTD) | B8: ='Income Statement'!I34 -> 3417018.7
A9: Total assets (Oct) | B9: ='Balance Sheet'!H17 -> 49124964
A10: Total liabilities (Oct) | B10: ='Balance Sheet'!H27 -> 20341859
A11: Total owners' equity (Oct) | B11: ='Balance Sheet'!H32 -> 28783105
A12: Closing cash (Oct) | B12: ='Balance Sheet'!H7 -> 13594797
A13: Operating cash flow (May–Oct) | B13: ='Cash Flow'!I15 -> 2184440.5
A14: Net change in cash (May–Oct) | B14: ='Cash Flow'!I27 -> -5026410.1
A16: Ratio scorecard (latest month) | B16: Value | C16: Classification | D16: Remark | E16: Score
A17: =Ratios!A26 -> Liquidity – Current Ratio | B17: =Ratios!H26 -> 2.7021587 | C17: =Ratios!I26 -> Caution | D17: =Ratios!J26 -> Average | E17: =IF(D17="N/A","",INDEX(Ratios!$B$50:$B$53,MATCH(D17,Ratios!$A$50:$A$53,0))) -> 1
A18: =Ratios!A27 -> Liquidity – Quick Ratio | B18: =Ratios!H27 -> 2.5052555 | C18: =Ratios!I27 -> Caution | D18: =Ratios!J27 -> Average | E18: =IF(D18="N/A","",INDEX(Ratios!$B$50:$B$53,MATCH(D18,Ratios!$A$50:$A$53,0))) -> 1
A19: =Ratios!A28 -> Solvency – Debt-to-Equity | B19: =Ratios!H28 -> 0.57965456 | C19: =Ratios!I28 -> Balanced | D19: =Ratios!J28 -> Average | E19: =IF(D19="N/A","",INDEX(Ratios!$B$50:$B$53,MATCH(D19,Ratios!$A$50:$A$53,0))) -> 1
A20: =Ratios!A29 -> Solvency – Interest Coverage | B20: =Ratios!H29 -> 27.058228 | C20: =Ratios!I29 -> Excellent | D20: =Ratios!J29 -> Excellent | E20: =IF(D20="N/A","",INDEX(Ratios!$B$50:$B$53,MATCH(D20,Ratios!$A$50:$A$53,0))) -> 3
A21: =Ratios!A30 -> Efficiency – Days Sales Outstanding | B21: =Ratios!H30 -> 144.70413 | C21: =Ratios!I30 -> Poor | D21: =Ratios!J30 -> Bad | E21: =IF(D21="N/A","",INDEX(Ratios!$B$50:$B$53,MATCH(D21,Ratios!$A$50:$A$53,0))) -> 0
A22: =Ratios!A31 -> Efficiency – Asset Turnover | B22: =Ratios!H31 -> 1.4555171 | C22: =Ratios!I31 -> Average | D22: =Ratios!J31 -> Average | E22: =IF(D22="N/A","",INDEX(Ratios!$B$50:$B$53,MATCH(D22,Ratios!$A$50:$A$53,0))) -> 1
A23: =Ratios!A32 -> Profitability – Gross Profit Margin | B23: =Ratios!H32 -> 0.80446982 | C23: =Ratios!I32 -> Excellent | D23: =Ratios!J32 -> Excellent | E23: =IF(D23="N/A","",INDEX(Ratios!$B$50:$B$53,MATCH(D23,Ratios!$A$50:$A$53,0))) -> 3
A24: =Ratios!A33 -> Profitability – Return on Assets | B24: =Ratios!H33 -> 0.11924174 | C24: =Ratios!I33 -> Good | D24: =Ratios!J33 -> Good | E24: =IF(D24="N/A","",INDEX(Ratios!$B$50:$B$53,MATCH(D24,Ratios!$A$50:$A$53,0))) -> 2
A25: =Ratios!A34 -> Profitability – Return on Equity | B25: =Ratios!H34 -> 0.20351336 | C25: =Ratios!I34 -> Excellent | D25: =Ratios!J34 -> Excellent | E25: =IF(D25="N/A","",INDEX(Ratios!$B$50:$B$53,MATCH(D25,Ratios!$A$50:$A$53,0))) -> 3
A27: Overall assessment | B27: Result
A28: Ratios rated (excl. N/A) | B28: =COUNT(E17:E25) -> 9
A29: Excellent | B29: =COUNTIF($D$17:$D$25,A29) -> 3
A30: Good | B30: =COUNTIF($D$17:$D$25,A30) -> 1
A31: Average | B31: =COUNTIF($D$17:$D$25,A31) -> 4
A32: Bad | B32: =COUNTIF($D$17:$D$25,A32) -> 1
A33: Average score (0 = Bad, 3 = Excellent) | B33: =AVERAGE(E17:E25) -> 1.6666667
A34: Overall verdict | B34: =IF(B33>=Ratios!E50,Ratios!D50,IF(B33>=Ratios!E51,Ratios!D51,IF(B33>=Ratios!E52,Ratios!D52,Ratios!D53))) -> Good
A35: Area(s) rated Bad | B35: {=IF(B32=0,"None",_xlfn.TEXTJOIN(", ",TRUE,IF(D17:D25="Bad",A17:A25,"")))} -> Efficiency – Days Sales Outstanding
A37: Statement integrity checks | B37: Status
A38: Balance Sheet balances (Apr–Oct) | B38: {=IF(SUMPRODUCT(ABS('Balance Sheet'!B35:H35))=0,"OK","ERROR")} -> OK
A39: Cash Flow closing cash agrees to Balance Sheet | B39: {=IF(SUMPRODUCT(ABS('Cash Flow'!C31:I31))=0,"OK","ERROR")} -> OK
A40: Income Statement net profit agrees to trial balance | B40: =IF('Income Statement'!I37=0,"OK","ERROR") -> OK
A41: All raw data mapped into trial balance summary | B41: {=IF(SUMPRODUCT(ABS('TB Summary'!E37:K38))=0,"OK","ERROR")} -> OK
A43: FINAL REMARK | B43: ="Overall business health: "&UPPER(B34)&"." -> Overall business health: GOOD.

Sheet Income Statement
A1: Income Statement (monthly, derived from cumulative YTD trial balance)
A2: Monthly, derived from cumulative YTD trial balance. Costs shown as negatives.
A4: Line item | B4: ='TB Summary'!E$4 -> 45777 | C4: ='TB Summary'!F$4 -> 45808 | D4: ='TB Summary'!G$4 -> 45838 | E4: ='TB Summary'!H$4 -> 45869 | F4: ='TB Summary'!I$4 -> 45900 | G4: ='TB Summary'!J$4 -> 45930 | H4: ='TB Summary'!K$4 -> 45961 | I4: YTD (Apr–Oct)
A5: Revenue
A6: Net Revenue | B6: =-'TB Summary'!E17 -> 5289325.3 | C6: =-('TB Summary'!F17-'TB Summary'!E17) -> 5772412.8 | D6: =-('TB Summary'!G17-'TB Summary'!F17) -> 6831641.5 | E6: =-('TB Summary'!H17-'TB Summary'!G17) -> 5172161.3 | F6: =-('TB Summary'!I17-'TB Summary'!H17) -> 6356565.9 | G6: =-('TB Summary'!J17-'TB Summary'!I17) -> 6948556.3 | H6: =-('TB Summary'!K17-'TB Summary'!J17) -> 5564437.9 | I6: =SUM(B6:H6) -> 41935101
A7: Revenue & cost (interco), net | B7: =-'TB Summary'!E16 -> 3526.565 | C7: =-('TB Summary'!F16-'TB Summary'!E16) -> -57232.762 | D7: =-('TB Summary'!G16-'TB Summary'!F16) -> -40515.735 | E7: =-('TB Summary'!H16-'TB Summary'!G16) -> -14122.435 | F7: =-('TB Summary'!I16-'TB Summary'!H16) -> -7675.837 | G7: =-('TB Summary'!J16-'TB Summary'!I16) -> -42807.841 | H7: =-('TB Summary'!K16-'TB Summary'!J16) -> -66643.064 | I7: =SUM(B7:H7) -> -225471.11
A8: Net Sales | B8: =B6+B7 -> 5292851.9 | C8: =C6+C7 -> 5715180.1 | D8: =D6+D7 -> 6791125.7 | E8: =E6+E7 -> 5158038.9 | F8: =F6+F7 -> 6348890.1 | G8: =G6+G7 -> 6905748.5 | H8: =H6+H7 -> 5497794.8 | I8: =I6+I7 -> 41709630
A9: Cost of Goods / Services Sold
A10: Cost of service delivery | B10: =-'TB Summary'!E24 -> -222457.78 | C10: =-('TB Summary'!F24-'TB Summary'!E24) -> -271587.43 | D10: =-('TB Summary'!G24-'TB Summary'!F24) -> -191123.26 | E10: =-('TB Summary'!H24-'TB Summary'!G24) -> -187052.03 | F10: =-('TB Summary'!I24-'TB Summary'!H24) -> -223471.87 | G10: =-('TB Summary'!J24-'TB Summary'!I24) -> -184173.75 | H10: =-('TB Summary'!K24-'TB Summary'!J24) -> -201042.49 | I10: =SUM(B10:H10) -> -1480908.6
A11: Cost of professional sub-contracting | B11: =-'TB Summary'!E25 -> -997173.88 | C11: =-('TB Summary'!F25-'TB Summary'!E25) -> -900935.52 | D11: =-('TB Summary'!G25-'TB Summary'!F25) -> -962158.09 | E11: =-('TB Summary'!H25-'TB Summary'!G25) -> -901497.08 | F11: =-('TB Summary'!I25-'TB Summary'!H25) -> -984859.58 | G11: =-('TB Summary'!J25-'TB Summary'!I25) -> -975027.17 | H11: =-('TB Summary'!K25-'TB Summary'!J25) -> -952931.32 | I11: =SUM(B11:H11) -> -6674582.6
A12: Total COGS | B12: =B10+B11 -> -1219631.7 | C12: =C10+C11 -> -1172523 | D12: =D10+D11 -> -1153281.4 | E12: =E10+E11 -> -1088549.1 | F12: =F10+F11 -> -1208331.5 | G12: =G10+G11 -> -1159200.9 | H12: =H10+H11 -> -1153973.8 | I12: =I10+I11 -> -8155491.3
A13: Gross Profit | B13: =B8+B12 -> 4073220.2 | C13: =C8+C12 -> 4542657.1 | D13: =D8+D12 -> 5637844.4 | E13: =E8+E12 -> 4069489.8 | F13: =F8+F12 -> 5140558.6 | G13: =G8+G12 -> 5746547.5 | H13: =H8+H12 -> 4343821 | I13: =I8+I12 -> 33554139
A14: Gross Profit Margin | B14: =IF(B8=0,0,B13/B8) -> 0.76957004 | C14: =IF(C8=0,0,C13/C8) -> 0.79484059 | D14: =IF(D8=0,0,D13/D8) -> 0.83017818 | E14: =IF(E8=0,0,E13/E8) -> 0.78896066 | F14: =IF(F8=0,0,F13/F8) -> 0.80967832 | G14: =IF(G8=0,0,G13/G8) -> 0.83213971 | H14: =IF(H8=0,0,H13/H8) -> 0.79010242 | I14: =IF(I8=0,0,I13/I8) -> 0.80446982
A15: Operating Expenses
A16: Salaries, wages and incentives | B16: =-'TB Summary'!E21 -> -3396549.7 | C16: =-('TB Summary'!F21-'TB Summary'!E21) -> -3614846.7 | D16: =-('TB Summary'!G21-'TB Summary'!F21) -> -3175877.8 | E16: =-('TB Summary'!H21-'TB Summary'!G21) -> -3592726.9 | F16: =-('TB Summary'!I21-'TB Summary'!H21) -> -3793629 | G16: =-('TB Summary'!J21-'TB Summary'!I21) -> -3360283.4 | H16: =-('TB Summary'!K21-'TB Summary'!J21) -> -3860490 | I16: =SUM(B16:H16) -> -24794403
A17: Recruitment and training | B17: =-'TB Summary'!E26 -> -103703.69 | C17: =-('TB Summary'!F26-'TB Summary'!E26) -> -69399.277 | D17: =-('TB Summary'!G26-'TB Summary'!F26) -> -98608.209 | E17: =-('TB Summary'!H26-'TB Summary'!G26) -> -85039.363 | F17: =-('TB Summary'!I26-'TB Summary'!H26) -> -55956.278 | G17: =-('TB Summary'!J26-'TB Summary'!I26) -> -79865.611 | H17: =-('TB Summary'!K26-'TB Summary'!J26) -> -100998.14 | I17: =SUM(B17:H17) -> -593570.57
A18: Travel, transport & conveyance | B18: =-'TB Summary'!E27 -> -92769.058 | C18: =-('TB Summary'!F27-'TB Summary'!E27) -> -74108.003 | D18: =-('TB Summary'!G27-'TB Summary'!F27) -> -149751.24 | E18: =-('TB Summary'!H27-'TB Summary'!G27) -> -88450.722 | F18: =-('TB Summary'!I27-'TB Summary'!H27) -> -97089.296 | G18: =-('TB Summary'!J27-'TB Summary'!I27) -> -73925.877 | H18: =-('TB Summary'!K27-'TB Summary'!J27) -> -104669.03 | I18: =SUM(B18:H18) -> -680763.23
A19: Rent, repairs, office expenses & local taxes | B19: =-'TB Summary'!E28 -> -114491.96 | C19: =-('TB Summary'!F28-'TB Summary'!E28) -> -155472.27 | D19: =-('TB Summary'!G28-'TB Summary'!F28) -> -149562.05 | E19: =-('TB Summary'!H28-'TB Summary'!G28) -> -183441.91 | F19: =-('TB Summary'!I28-'TB Summary'!H28) -> -153593.04 | G19: =-('TB Summary'!J28-'TB Summary'!I28) -> -138759.31 | H19: =-('TB Summary'!K28-'TB Summary'!J28) -> -149015.19 | I19: =SUM(B19:H19) -> -1044335.7
A20: Legal and professional fees | B20: =-'TB Summary'!E29 -> -140924.46 | C20: =-('TB Summary'!F29-'TB Summary'!E29) -> -118686.8 | D20: =-('TB Summary'!G29-'TB Summary'!F29) -> -102593.07 | E20: =-('TB Summary'!H29-'TB Summary'!G29) -> -171443.91 | F20: =-('TB Summary'!I29-'TB Summary'!H29) -> -174797.1 | G20: =-('TB Summary'!J29-'TB Summary'!I29) -> -84577.343 | H20: =-('TB Summary'!K29-'TB Summary'!J29) -> -178690.93 | I20: =SUM(B20:H20) -> -971713.61
A21: Other expenses | B21: =-'TB Summary'!E30 -> -37172.471 | C21: =-('TB Summary'!F30-'TB Summary'!E30) -> -35814.72 | D21: =-('TB Summary'!G30-'TB Summary'!F30) -> -38865.837 | E21: =-('TB Summary'!H30-'TB Summary'!G30) -> -24109.558 | F21: =-('TB Summary'!I30-'TB Summary'!H30) -> -27087.878 | G21: =-('TB Summary'!J30-'TB Summary'!I30) -> -23654.395 | H21: =-('TB Summary'!K30-'TB Summary'!J30) -> -17310.299 | I21: =SUM(B21:H21) -> -204015.16
A22: CSR expenses | B22: =-'TB Summary'!E31 -> -7750 | C22: =-('TB Summary'!F31-'TB Summary'!E31) -> -7750 | D22: =-('TB Summary'!G31-'TB Summary'!F31) -> -7910.054 | E22: =-('TB Summary'!H31-'TB Summary'!G31) -> -7803.351 | F22: =-('TB Summary'!I31-'TB Summary'!H31) -> -7803.351 | G22: =-('TB Summary'!J31-'TB Summary'!I31) -> -14160.741 | H22: =-('TB Summary'!K31-'TB Summary'!J31) -> -8671.284 | I22: =SUM(B22:H22) -> -61848.781
A23: Employee reimbursements | B23: =-'TB Summary'!E32 -> -7254.831 | C23: =-('TB Summary'!F32-'TB Summary'!E32) -> 13569.986 | D23: =-('TB Summary'!G32-'TB Summary'!F32) -> -29429.614 | E23: =-('TB Summary'!H32-'TB Summary'!G32) -> -15864.683 | F23: =-('TB Summary'!I32-'TB Summary'!H32) -> -17822.183 | G23: =-('TB Summary'!J32-'TB Summary'!I32) -> -16218.794 | H23: =-('TB Summary'!K32-'TB Summary'!J32) -> -15833.99 | I23: =SUM(B23:H23) -> -88854.109
A24: Depreciation and amortization | B24: =-'TB Summary'!E23 -> -104098 | C24: =-('TB Summary'!F23-'TB Summary'!E23) -> -107612.69 | D24: =-('TB Summary'!G23-'TB Summary'!F23) -> -103988.18 | E24: =-('TB Summary'!H23-'TB Summary'!G23) -> -106563.52 | F24: =-('TB Summary'!I23-'TB Summary'!H23) -> -114695.14 | G24: =-('TB Summary'!J23-'TB Summary'!I23) -> -110796.62 | H24: =-('TB Summary'!K23-'TB Summary'!J23) -> -114287.32 | I24: =SUM(B24:H24) -> -762041.48
A25: Gain / (loss) on sale of fixed assets | B25: =-'TB Summary'!E19 -> 0 | C25: =-('TB Summary'!F19-'TB Summary'!E19) -> 6731.031 | D25: =-('TB Summary'!G19-'TB Summary'!F19) -> -1504.18 | E25: =-('TB Summary'!H19-'TB Summary'!G19) -> -4797.771 | F25: =-('TB Summary'!I19-'TB Summary'!H19) -> 3795.69 | G25: =-('TB Summary'!J19-'TB Summary'!I19) -> -0.006 | H25: =-('TB Summary'!K19-'TB Summary'!J19) -> -154.291 | I25: =SUM(B25:H25) -> 4070.473
A26: Total Operating Expenses | B26: =SUM(B16:B25) -> -4004714.1 | C26: =SUM(C16:C25) -> -4163389.4 | D26: =SUM(D16:D25) -> -3858090.3 | E26: =SUM(E16:E25) -> -4280241.7 | F26: =SUM(F16:F25) -> -4438677.5 | G26: =SUM(G16:G25) -> -3902242.1 | H26: =SUM(H16:H25) -> -4550120.5 | I26: =SUM(I16:I25) -> -29197476
A27: Operating Profit (EBIT) | B27: =B13+B26 -> 68506.113 | C27: =C13+C26 -> 379267.69 | D27: =D13+D26 -> 1779754.1 | E27: =E13+E26 -> -210751.92 | F27: =F13+F26 -> 701881.08 | G27: =G13+G26 -> 1844305.5 | H27: =H13+H26 -> -206299.49 | I27: =I13+I26 -> 4356663.1
A28: Non-operating items
A29: Other income | B29: =-'TB Summary'!E18 -> 112645.21 | C29: =-('TB Summary'!F18-'TB Summary'!E18) -> 101091.16 | D29: =-('TB Summary'!G18-'TB Summary'!F18) -> 101365.53 | E29: =-('TB Summary'!H18-'TB Summary'!G18) -> 4734.459 | F29: =-('TB Summary'!I18-'TB Summary'!H18) -> -30695.437 | G29: =-('TB Summary'!J18-'TB Summary'!I18) -> 40236.595 | H29: =-('TB Summary'!K18-'TB Summary'!J18) -> 37364.289 | I29: =SUM(B29:H29) -> 366741.81
A30: Interest on interco. loan (net) | B30: =-'TB Summary'!E20 -> -0.266 | C30: =-('TB Summary'!F20-'TB Summary'!E20) -> 5.464 | D30: =-('TB Summary'!G20-'TB Summary'!F20) -> 24.029 | E30: =-('TB Summary'!H20-'TB Summary'!G20) -> 45.821 | F30: =-('TB Summary'!I20-'TB Summary'!H20) -> 54.396 | G30: =-('TB Summary'!J20-'TB Summary'!I20) -> -28.938 | H30: =-('TB Summary'!K20-'TB Summary'!J20) -> -31.074 | I30: =SUM(B30:H30) -> 69.432
A31: Finance costs | B31: =-'TB Summary'!E22 -> -15169.964 | C31: =-('TB Summary'!F22-'TB Summary'!E22) -> -16220.51 | D31: =-('TB Summary'!G22-'TB Summary'!F22) -> -19034.293 | E31: =-('TB Summary'!H22-'TB Summary'!G22) -> -19912.712 | F31: =-('TB Summary'!I22-'TB Summary'!H22) -> -33344.073 | G31: =-('TB Summary'!J22-'TB Summary'!I22) -> -36723.183 | H31: =-('TB Summary'!K22-'TB Summary'!J22) -> -20605.924 | I31: =SUM(B31:H31) -> -161010.66
A32: Profit Before Tax | B32: =B27+SUM(B29:B31) -> 165981.09 | C32: =C27+SUM(C29:C31) -> 464143.81 | D32: =D27+SUM(D29:D31) -> 1862109.4 | E32: =E27+SUM(E29:E31) -> -225884.35 | F32: =F27+SUM(F29:F31) -> 637895.97 | G32: =G27+SUM(G29:G31) -> 1847789.9 | H32: =H27+SUM(H29:H31) -> -189572.2 | I32: =I27+SUM(I29:I31) -> 4562463.6
A33: Income tax | B33: =-'TB Summary'!E33 -> -11141.522 | C33: =-('TB Summary'!F33-'TB Summary'!E33) -> 2895.462 | D33: =-('TB Summary'!G33-'TB Summary'!F33) -> -637356.53 | E33: =-('TB Summary'!H33-'TB Summary'!G33) -> 58292.033 | F33: =-('TB Summary'!I33-'TB Summary'!H33) -> -899.066 | G33: =-('TB Summary'!J33-'TB Summary'!I33) -> -554978.23 | H33: =-('TB Summary'!K33-'TB Summary'!J33) -> -2257.105 | I33: =SUM(B33:H33) -> -1145445
A34: Net Profit | B34: =B32+B33 -> 154839.57 | C34: =C32+C33 -> 467039.27 | D34: =D32+D33 -> 1224752.9 | E34: =E32+E33 -> -167592.32 | F34: =F32+F33 -> 636996.9 | G34: =G32+G33 -> 1292811.7 | H34: =H32+H33 -> -191829.31 | I34: =I32+I33 -> 3417018.7
A35: Net Profit Margin | B35: =IF(B8=0,0,B34/B8) -> 0.029254469 | C35: =IF(C8=0,0,C34/C8) -> 0.081719082 | D35: =IF(D8=0,0,D34/D8) -> 0.18034607 | E35: =IF(E8=0,0,E34/E8) -> -0.03249148 | F35: =IF(F8=0,0,F34/F8) -> 0.10033201 | G35: =IF(G8=0,0,G34/G8) -> 0.18720805 | H35: =IF(H8=0,0,H34/H8) -> -0.034892045 | I35: =IF(I8=0,0,I34/I8) -> 0.081923975
A37: Check: YTD net profit vs trial balance (should be 0) | I37: =ROUND(I34-'TB Summary'!K35,0) -> 0

Sheet Balance Sheet
A1: Balance Sheet (month-end, all companies consolidated)
A2: Month-end, all companies consolidated
A4: Line item | B4: ='TB Summary'!E$4 -> 45777 | C4: ='TB Summary'!F$4 -> 45808 | D4: ='TB Summary'!G$4 -> 45838 | E4: ='TB Summary'!H$4 -> 45869 | F4: ='TB Summary'!I$4 -> 45900 | G4: ='TB Summary'!J$4 -> 45930 | H4: ='TB Summary'!K$4 -> 45961
A5: ASSETS
A6: Current Assets
A7: Cash, bank, FDs & investments | B7: ='TB Summary'!E7 -> 18621208 | C7: ='TB Summary'!F7 -> 18528228 | D7: ='TB Summary'!G7 -> 18663213 | E7: ='TB Summary'!H7 -> 18157595 | F7: ='TB Summary'!I7 -> 18778304 | G7: ='TB Summary'!J7 -> 12318272 | H7: ='TB Summary'!K7 -> 13594797
A8: Trade receivables & unbilled revenue | B8: ='TB Summary'!E10 -> 26693473 | C8: ='TB Summary'!F10 -> 25194603 | D8: ='TB Summary'!G10 -> 27376325 | E8: ='TB Summary'!H10 -> 28192677 | F8: ='TB Summary'!I10 -> 26003064 | G8: ='TB Summary'!J10 -> 27157526 | H8: ='TB Summary'!K10 -> 28203532
A9: Income tax & deferred tax assets | B9: ='TB Summary'!E11 -> 1633432.4 | C9: ='TB Summary'!F11 -> 1738354.7 | D9: ='TB Summary'!G11 -> 1404231.3 | E9: ='TB Summary'!H11 -> 1561606.6 | F9: ='TB Summary'!I11 -> 1665493.5 | G9: ='TB Summary'!J11 -> 1741381 | H9: ='TB Summary'!K11 -> 1800281.2
A10: Other assets | B10: ='TB Summary'!E9 -> 1232168.9 | C10: ='TB Summary'!F9 -> 1274561.2 | D10: ='TB Summary'!G9 -> 1362766.2 | E10: ='TB Summary'!H9 -> 1787036 | F10: ='TB Summary'!I9 -> 1676810.7 | G10: ='TB Summary'!J9 -> 1599013 | H10: ='TB Summary'!K9 -> 1484902.5
A11: Total Current Assets | B11: =SUM(B7:B10) -> 48180282 | C11: =SUM(C7:C10) -> 46735747 | D11: =SUM(D7:D10) -> 48806536 | E11: =SUM(E7:E10) -> 49698914 | F11: =SUM(F7:F10) -> 48123673 | G11: =SUM(G7:G10) -> 42816192 | H11: =SUM(H7:H10) -> 45083513
A12: Non-Current Assets
A13: PPE & intangibles | B13: ='TB Summary'!E5 -> 4108318.8 | C13: ='TB Summary'!F5 -> 4092358.3 | D13: ='TB Summary'!G5 -> 4166361.9 | E13: ='TB Summary'!H5 -> 4160953.9 | F13: ='TB Summary'!I5 -> 4265861.5 | G13: ='TB Summary'!J5 -> 4237690.7 | H13: ='TB Summary'!K5 -> 4161494.1
A14: Goodwill | B14: ='TB Summary'!E6 -> 83942.334 | C14: ='TB Summary'!F6 -> 82402.121 | D14: ='TB Summary'!G6 -> 80092.229 | E14: ='TB Summary'!H6 -> 76394.458 | F14: ='TB Summary'!I6 -> 72965.501 | G14: ='TB Summary'!J6 -> 70600.753 | H14: ='TB Summary'!K6 -> 67771.199
A15: Other financial assets | B15: ='TB Summary'!E8 -> 484888.92 | C15: ='TB Summary'!F8 -> 385300.57 | D15: ='TB Summary'!G8 -> 199512.99 | E15: ='TB Summary'!H8 -> 226108.44 | F15: ='TB Summary'!I8 -> 191140.7 | G15: ='TB Summary'!J8 -> 56565.475 | H15: ='TB Summary'!K8 -> -187814.82
A16: Total Non-Current Assets | B16: =SUM(B13:B15) -> 4677150.1 | C16: =SUM(C13:C15) -> 4560061 | D16: =SUM(D13:D15) -> 4445967.1 | E16: =SUM(E13:E15) -> 4463456.8 | F16: =SUM(F13:F15) -> 4529967.7 | G16: =SUM(G13:G15) -> 4364857 | H16: =SUM(H13:H15) -> 4041450.4
A17: TOTAL ASSETS | B17: =B11+B16 -> 52857432 | C17: =C11+C16 -> 51295808 | D17: =D11+D16 -> 53252503 | E17: =E11+E16 -> 54162371 | F17: =F11+F16 -> 52653640 | G17: =G11+G16 -> 47181048 | H17: =H11+H16 -> 49124964
A19: LIABILITIES
A20: Current Liabilities
A21: Financial liabilities | B21: =-'TB Summary'!E13 -> 16283078 | C21: =-'TB Summary'!F13 -> 13481367 | D21: =-'TB Summary'!G13 -> 14841656 | E21: =-'TB Summary'!H13 -> 14260134 | F21: =-'TB Summary'!I13 -> 14492842 | G21: =-'TB Summary'!J13 -> 15089237 | H21: =-'TB Summary'!K13 -> 16684258
A22: Total Current Liabilities | B22: =B21 -> 16283078 | C22: =C21 -> 13481367 | D22: =D21 -> 14841656 | E22: =E21 -> 14260134 | F22: =F21 -> 14492842 | G22: =G21 -> 15089237 | H22: =H21 -> 16684258
A23: Non-Current Liabilities
A24: Other liabilities | B24: =-'TB Summary'!E14 -> 2052362.6 | C24: =-'TB Summary'!F14 -> 2478575.9 | D24: =-'TB Summary'!G14 -> 1569837.4 | E24: =-'TB Summary'!H14 -> 3132398.1 | F24: =-'TB Summary'!I14 -> 1801856.2 | G24: =-'TB Summary'!J14 -> 1564934.5 | H24: =-'TB Summary'!K14 -> 1879201.1
A25: Provisions | B25: =-'TB Summary'!E15 -> 1407207.5 | C25: =-'TB Summary'!F15 -> 1486230.5 | D25: =-'TB Summary'!G15 -> 1537015.3 | E25: =-'TB Summary'!H15 -> 1584383.8 | F25: =-'TB Summary'!I15 -> 1645791.3 | G25: =-'TB Summary'!J15 -> 1682503 | H25: =-'TB Summary'!K15 -> 1778399.2
A26: Total Non-Current Liabilities | B26: =SUM(B24:B25) -> 3459570.1 | C26: =SUM(C24:C25) -> 3964806.4 | D26: =SUM(D24:D25) -> 3106852.7 | E26: =SUM(E24:E25) -> 4716781.9 | F26: =SUM(F24:F25) -> 3447647.6 | G26: =SUM(G24:G25) -> 3247437.4 | H26: =SUM(H24:H25) -> 3657600.3
A27: TOTAL LIABILITIES | B27: =B22+B26 -> 19742648 | C27: =C22+C26 -> 17446173 | D27: =D22+D26 -> 17948508 | E27: =E22+E26 -> 18976916 | F27: =F22+F26 -> 17940490 | G27: =G22+G26 -> 18336675 | H27: =H22+H26 -> 20341859
A29: OWNERS' EQUITY
A30: Owners' equity (share capital & reserves) | B30: =-'TB Summary'!E12 -> 32959944 | C30: =-'TB Summary'!F12 -> 33227756 | D30: =-'TB Summary'!G12 -> 33457363 | E30: =-'TB Summary'!H12 -> 33506416 | F30: =-'TB Summary'!I12 -> 32397114 | G30: =-'TB Summary'!J12 -> 25235526 | H30: =-'TB Summary'!K12 -> 25366086
A31: Current-year retained earnings (YTD net profit) | B31: =SUM('Income Statement'!$B$34:B34) -> 154839.57 | C31: =SUM('Income Statement'!$B$34:C34) -> 621878.84 | D31: =SUM('Income Statement'!$B$34:D34) -> 1846631.7 | E31: =SUM('Income Statement'!$B$34:E34) -> 1679039.4 | F31: =SUM('Income Statement'!$B$34:F34) -> 2316036.3 | G31: =SUM('Income Statement'!$B$34:G34) -> 3608848 | H31: =SUM('Income Statement'!$B$34:H34) -> 3417018.7
A32: TOTAL OWNERS' EQUITY | B32: =B30+B31 -> 33114784 | C32: =C30+C31 -> 33849635 | D32: =D30+D31 -> 35303995 | E32: =E30+E31 -> 35185455 | F32: =F30+F31 -> 34713150 | G32: =G30+G31 -> 28844374 | H32: =H30+H31 -> 28783105
A33: TOTAL LIABILITIES & EQUITY | B33: =B27+B32 -> 52857432 | C33: =C27+C32 -> 51295808 | D33: =D27+D32 -> 53252503 | E33: =E27+E32 -> 54162371 | F33: =F27+F32 -> 52653640 | G33: =G27+G32 -> 47181048 | H33: =H27+H32 -> 49124964
A35: Check: Assets – (Liabilities + Equity) (should be 0) | B35: =ROUND(B17-B33,0) -> 0 | C35: =ROUND(C17-C33,0) -> 0 | D35: =ROUND(D17-D33,0) -> 0 | E35: =ROUND(E17-E33,0) -> 0 | F35: =ROUND(F17-F33,0) -> 0 | G35: =ROUND(G17-G33,0) -> 0 | H35: =ROUND(H17-H33,0) -> 0

Sheet Cash Flow
A1: Cash Flow Statement (indirect method, monthly)
A2: Indirect method. Apr is the opening position; flows shown May–Oct.
A4: Line item | B4: ='TB Summary'!E$4 -> 45777 | C4: ='TB Summary'!F$4 -> 45808 | D4: ='TB Summary'!G$4 -> 45838 | E4: ='TB Summary'!H$4 -> 45869 | F4: ='TB Summary'!I$4 -> 45900 | G4: ='TB Summary'!J$4 -> 45930 | H4: ='TB Summary'!K$4 -> 45961 | I4: Total May–Oct
A5: OPERATING ACTIVITIES
A6: Net profit | C6: ='Income Statement'!C34 -> 467039.27 | D6: ='Income Statement'!D34 -> 1224752.9 | E6: ='Income Statement'!E34 -> -167592.32 | F6: ='Income Statement'!F34 -> 636996.9 | G6: ='Income Statement'!G34 -> 1292811.7 | H6: ='Income Statement'!H34 -> -191829.31 | I6: =SUM(C6:H6) -> 3262179.1
A7: Add: depreciation and amortization | C7: =-'Income Statement'!C24 -> 107612.69 | D7: =-'Income Statement'!D24 -> 103988.18 | E7: =-'Income Statement'!E24 -> 106563.52 | F7: =-'Income Statement'!F24 -> 114695.14 | G7: =-'Income Statement'!G24 -> 110796.62 | H7: =-'Income Statement'!H24 -> 114287.32 | I7: =SUM(C7:H7) -> 657943.48
A8: Add: (gain) / loss on sale of fixed assets | C8: =-'Income Statement'!C25 -> -6731.031 | D8: =-'Income Statement'!D25 -> 1504.18 | E8: =-'Income Statement'!E25 -> 4797.771 | F8: =-'Income Statement'!F25 -> -3795.69 | G8: =-'Income Statement'!G25 -> 0.006 | H8: =-'Income Statement'!H25 -> 154.291 | I8: =SUM(C8:H8) -> -4070.473
A9: Changes in working capital
A10: (Increase) / decrease in trade receivables | C10: =-('Balance Sheet'!C8-'Balance Sheet'!B8) -> 1498870.1 | D10: =-('Balance Sheet'!D8-'Balance Sheet'!C8) -> -2181722.7 | E10: =-('Balance Sheet'!E8-'Balance Sheet'!D8) -> -816351.36 | F10: =-('Balance Sheet'!F8-'Balance Sheet'!E8) -> 2189612.3 | G10: =-('Balance Sheet'!G8-'Balance Sheet'!F8) -> -1154461.5 | H10: =-('Balance Sheet'!H8-'Balance Sheet'!G8) -> -1046006.2 | I10: =SUM(C10:H10) -> -1510059.3
A11: (Increase) / decrease in income tax & deferred tax assets | C11: =-('Balance Sheet'!C9-'Balance Sheet'!B9) -> -104922.37 | D11: =-('Balance Sheet'!D9-'Balance Sheet'!C9) -> 334123.47 | E11: =-('Balance Sheet'!E9-'Balance Sheet'!D9) -> -157375.34 | F11: =-('Balance Sheet'!F9-'Balance Sheet'!E9) -> -103886.86 | G11: =-('Balance Sheet'!G9-'Balance Sheet'!F9) -> -75887.515 | H11: =-('Balance Sheet'!H9-'Balance Sheet'!G9) -> -58900.231 | I11: =SUM(C11:H11) -> -166848.84
A12: (Increase) / decrease in other assets | C12: =-('Balance Sheet'!C10-'Balance Sheet'!B10) -> -42392.339 | D12: =-('Balance Sheet'!D10-'Balance Sheet'!C10) -> -88204.941 | E12: =-('Balance Sheet'!E10-'Balance Sheet'!D10) -> -424269.81 | F12: =-('Balance Sheet'!F10-'Balance Sheet'!E10) -> 110225.34 | G12: =-('Balance Sheet'!G10-'Balance Sheet'!F10) -> 77797.649 | H12: =-('Balance Sheet'!H10-'Balance Sheet'!G10) -> 114110.55 | I12: =SUM(C12:H12) -> -252733.56
A13: Increase / (decrease) in other liabilities | C13: ='Balance Sheet'!C24-'Balance Sheet'!B24 -> 426213.27 | D13: ='Balance Sheet'!D24-'Balance Sheet'!C24 -> -908738.52 | E13: ='Balance Sheet'!E24-'Balance Sheet'!D24 -> 1562560.7 | F13: ='Balance Sheet'!F24-'Balance Sheet'!E24 -> -1330541.9 | G13: ='Balance Sheet'!G24-'Balance Sheet'!F24 -> -236921.75 | H13: ='Balance Sheet'!H24-'Balance Sheet'!G24 -> 314266.6 | I13: =SUM(C13:H13) -> -173161.54
A14: Increase / (decrease) in provisions | C14: ='Balance Sheet'!C25-'Balance Sheet'!B25 -> 79022.949 | D14: ='Balance Sheet'!D25-'Balance Sheet'!C25 -> 50784.819 | E14: ='Balance Sheet'!E25-'Balance Sheet'!D25 -> 47368.521 | F14: ='Balance Sheet'!F25-'Balance Sheet'!E25 -> 61407.543 | G14: ='Balance Sheet'!G25-'Balance Sheet'!F25 -> 36711.61 | H14: ='Balance Sheet'!H25-'Balance Sheet'!G25 -> 95896.22 | I14: =SUM(C14:H14) -> 371191.66
A15: Net Cash from Operating Activities | C15: =SUM(C6:C8)+SUM(C10:C14) -> 2424712.5 | D15: =SUM(D6:D8)+SUM(D10:D14) -> -1463512.7 | E15: =SUM(E6:E8)+SUM(E10:E14) -> 155701.71 | F15: =SUM(F6:F8)+SUM(F10:F14) -> 1674712.8 | G15: =SUM(G6:G8)+SUM(G10:G14) -> 50846.881 | H15: =SUM(H6:H8)+SUM(H10:H14) -> -658020.76 | I15: =SUM(I6:I8)+SUM(I10:I14) -> 2184440.5
A17: INVESTING ACTIVITIES
A18: Net (purchase) / disposal of PPE, intangibles & goodwill | C18: =-(('Balance Sheet'!C13-'Balance Sheet'!B13)+('Balance Sheet'!C14-'Balance Sheet'!B14)+C7+C8) -> -83380.895 | D18: =-(('Balance Sheet'!D13-'Balance Sheet'!C13)+('Balance Sheet'!D14-'Balance Sheet'!C14)+D7+D8) -> -177186.12 | E18: =-(('Balance Sheet'!E13-'Balance Sheet'!D13)+('Balance Sheet'!E14-'Balance Sheet'!D14)+E7+E8) -> -102255.49 | F18: =-(('Balance Sheet'!F13-'Balance Sheet'!E13)+('Balance Sheet'!F14-'Balance Sheet'!E14)+F7+F8) -> -212378.07 | G18: =-(('Balance Sheet'!G13-'Balance Sheet'!F13)+('Balance Sheet'!G14-'Balance Sheet'!F14)+G7+G8) -> -80261.151 | H18: =-(('Balance Sheet'!H13-'Balance Sheet'!G13)+('Balance Sheet'!H14-'Balance Sheet'!G14)+H7+H8) -> -35415.377 | I18: =SUM(C18:H18) -> -690877.11
A19: (Increase) / decrease in other financial assets | C19: =-('Balance Sheet'!C15-'Balance Sheet'!B15) -> 99588.349 | D19: =-('Balance Sheet'!D15-'Balance Sheet'!C15) -> 185787.58 | E19: =-('Balance Sheet'!E15-'Balance Sheet'!D15) -> -26595.448 | F19: =-('Balance Sheet'!F15-'Balance Sheet'!E15) -> 34967.741 | G19: =-('Balance Sheet'!G15-'Balance Sheet'!F15) -> 134575.23 | H19: =-('Balance Sheet'!H15-'Balance Sheet'!G15) -> 244380.29 | I19: =SUM(C19:H19) -> 672703.74
A20: Net Cash from Investing Activities | C20: =SUM(C18:C19) -> 16207.454 | D20: =SUM(D18:D19) -> 8601.459 | E20: =SUM(E18:E19) -> -128850.94 | F20: =SUM(F18:F19) -> -177410.33 | G20: =SUM(G18:G19) -> 54314.076 | H20: =SUM(H18:H19) -> 208964.92 | I20: =SUM(I18:I19) -> -18173.37
A22: FINANCING ACTIVITIES
A23: Net borrowings / (repayments) of financial liabilities | C23: ='Balance Sheet'!C21-'Balance Sheet'!B21 -> -2801711.3 | D23: ='Balance Sheet'!D21-'Balance Sheet'!C21 -> 1360289 | E23: ='Balance Sheet'!E21-'Balance Sheet'!D21 -> -581521.89 | F23: ='Balance Sheet'!F21-'Balance Sheet'!E21 -> 232708.54 | G23: ='Balance Sheet'!G21-'Balance Sheet'!F21 -> 596395.08 | H23: ='Balance Sheet'!H21-'Balance Sheet'!G21 -> 1595020.8 | I23: =SUM(C23:H23) -> 401180.26
A24: Change in owners' equity (capital, distributions, other) | C24: ='Balance Sheet'!C30-'Balance Sheet'!B30 -> 267811.98 | D24: ='Balance Sheet'!D30-'Balance Sheet'!C30 -> 229606.93 | E24: ='Balance Sheet'!E30-'Balance Sheet'!D30 -> 49053.107 | F24: ='Balance Sheet'!F30-'Balance Sheet'!E30 -> -1109301.8 | G24: ='Balance Sheet'!G30-'Balance Sheet'!F30 -> -7161588.6 | H24: ='Balance Sheet'!H30-'Balance Sheet'!G30 -> 130560.8 | I24: =SUM(C24:H24) -> -7593857.5
A25: Net Cash from Financing Activities | C25: =SUM(C23:C24) -> -2533899.3 | D25: =SUM(D23:D24) -> 1589895.9 | E25: =SUM(E23:E24) -> -532468.78 | F25: =SUM(F23:F24) -> -876593.22 | G25: =SUM(G23:G24) -> -6565193.5 | H25: =SUM(H23:H24) -> 1725581.6 | I25: =SUM(I23:I24) -> -7192677.3
A27: NET CHANGE IN CASH | C27: =C15+C20+C25 -> -92979.357 | D27: =D15+D20+D25 -> 134984.72 | E27: =E15+E20+E25 -> -505618.02 | F27: =F15+F20+F25 -> 620709.28 | G27: =G15+G20+G25 -> -6460032.5 | H27: =H15+H20+H25 -> 1276525.8 | I27: =I15+I20+I25 -> -5026410.1
A28: Opening cash | C28: ='Balance Sheet'!B7 -> 18621208 | D28: ='Balance Sheet'!C7 -> 18528228 | E28: ='Balance Sheet'!D7 -> 18663213 | F28: ='Balance Sheet'!E7 -> 18157595 | G28: ='Balance Sheet'!F7 -> 18778304 | H28: ='Balance Sheet'!G7 -> 12318272 | I28: =C28 -> 18621208
A29: CLOSING CASH | C29: =C27+C28 -> 18528228 | D29: =D27+D28 -> 18663213 | E29: =E27+E28 -> 18157595 | F29: =F27+F28 -> 18778304 | G29: =G27+G28 -> 12318272 | H29: =H27+H28 -> 13594797 | I29: =I27+I28 -> 13594797
A30: Cash per Balance Sheet | C30: ='Balance Sheet'!C7 -> 18528228 | D30: ='Balance Sheet'!D7 -> 18663213 | E30: ='Balance Sheet'!E7 -> 18157595 | F30: ='Balance Sheet'!F7 -> 18778304 | G30: ='Balance Sheet'!G7 -> 12318272 | H30: ='Balance Sheet'!H7 -> 13594797 | I30: ='Balance Sheet'!H7 -> 13594797
A31: Check: closing cash vs Balance Sheet (should be 0) | C31: =ROUND(C29-C30,0) -> 0 | D31: =ROUND(D29-D30,0) -> 0 | E31: =ROUND(E29-E30,0) -> 0 | F31: =ROUND(F29-F30,0) -> 0 | G31: =ROUND(G29-G30,0) -> 0 | H31: =ROUND(H29-H30,0) -> 0 | I31: =ROUND(I29-I30,0) -> 0

Sheet Ratios
A1: Financial Ratio Analysis (cumulative YTD, Apr–Oct)
A2: YTD figures; ROA, ROE and asset turnover annualized. Ratings use the cheat sheet bands; Rating and Remark columns show the latest month.
A4: Fiscal year start month (input) | B4: 4
A6: Supporting data | B6: ='TB Summary'!E$4 -> 45777 | C6: ='TB Summary'!F$4 -> 45808 | D6: ='TB Summary'!G$4 -> 45838 | E6: ='TB Summary'!H$4 -> 45869 | F6: ='TB Summary'!I$4 -> 45900 | G6: ='TB Summary'!J$4 -> 45930 | H6: ='TB Summary'!K$4 -> 45961
A7: Months elapsed in fiscal year | B7: =MOD(MONTH(B$6)-$B$4,12)+1 -> 1 | C7: =MOD(MONTH(C$6)-$B$4,12)+1 -> 2 | D7: =MOD(MONTH(D$6)-$B$4,12)+1 -> 3 | E7: =MOD(MONTH(E$6)-$B$4,12)+1 -> 4 | F7: =MOD(MONTH(F$6)-$B$4,12)+1 -> 5 | G7: =MOD(MONTH(G$6)-$B$4,12)+1 -> 6 | H7: =MOD(MONTH(H$6)-$B$4,12)+1 -> 7
A8: Days elapsed in fiscal year | B8: =B$6-DATE(YEAR(B$6)-IF(MONTH(B$6)<$B$4,1,0),$B$4,1)+1 -> 30 | C8: =C$6-DATE(YEAR(C$6)-IF(MONTH(C$6)<$B$4,1,0),$B$4,1)+1 -> 61 | D8: =D$6-DATE(YEAR(D$6)-IF(MONTH(D$6)<$B$4,1,0),$B$4,1)+1 -> 91 | E8: =E$6-DATE(YEAR(E$6)-IF(MONTH(E$6)<$B$4,1,0),$B$4,1)+1 -> 122 | F8: =F$6-DATE(YEAR(F$6)-IF(MONTH(F$6)<$B$4,1,0),$B$4,1)+1 -> 153 | G8: =G$6-DATE(YEAR(G$6)-IF(MONTH(G$6)<$B$4,1,0),$B$4,1)+1 -> 183 | H8: =H$6-DATE(YEAR(H$6)-IF(MONTH(H$6)<$B$4,1,0),$B$4,1)+1 -> 214
A9: Annualization factor (12 / months elapsed) | B9: =12/B7 -> 12 | C9: =12/C7 -> 6 | D9: =12/D7 -> 4 | E9: =12/E7 -> 3 | F9: =12/F7 -> 2.4 | G9: =12/G7 -> 2 | H9: =12/H7 -> 1.7142857
A10: Total current assets | B10: ='Balance Sheet'!B11 -> 48180282 | C10: ='Balance Sheet'!C11 -> 46735747 | D10: ='Balance Sheet'!D11 -> 48806536 | E10: ='Balance Sheet'!E11 -> 49698914 | F10: ='Balance Sheet'!F11 -> 48123673 | G10: ='Balance Sheet'!G11 -> 42816192 | H10: ='Balance Sheet'!H11 -> 45083513
A11: Total current liabilities | B11: ='Balance Sheet'!B22 -> 16283078 | C11: ='Balance Sheet'!C22 -> 13481367 | D11: ='Balance Sheet'!D22 -> 14841656 | E11: ='Balance Sheet'!E22 -> 14260134 | F11: ='Balance Sheet'!F22 -> 14492842 | G11: ='Balance Sheet'!G22 -> 15089237 | H11: ='Balance Sheet'!H22 -> 16684258
A12: Cash & investments | B12: ='Balance Sheet'!B7 -> 18621208 | C12: ='Balance Sheet'!C7 -> 18528228 | D12: ='Balance Sheet'!D7 -> 18663213 | E12: ='Balance Sheet'!E7 -> 18157595 | F12: ='Balance Sheet'!F7 -> 18778304 | G12: ='Balance Sheet'!G7 -> 12318272 | H12: ='Balance Sheet'!H7 -> 13594797
A13: Trade receivables | B13: ='Balance Sheet'!B8 -> 26693473 | C13: ='Balance Sheet'!C8 -> 25194603 | D13: ='Balance Sheet'!D8 -> 27376325 | E13: ='Balance Sheet'!E8 -> 28192677 | F13: ='Balance Sheet'!F8 -> 26003064 | G13: ='Balance Sheet'!G8 -> 27157526 | H13: ='Balance Sheet'!H8 -> 28203532
A14: Inventory | B14: 0 | C14: 0 | D14: 0 | E14: 0 | F14: 0 | G14: 0 | H14: 0
A15: Total debt (financial liabilities) | B15: ='Balance Sheet'!B21 -> 16283078 | C15: ='Balance Sheet'!C21 -> 13481367 | D15: ='Balance Sheet'!D21 -> 14841656 | E15: ='Balance Sheet'!E21 -> 14260134 | F15: ='Balance Sheet'!F21 -> 14492842 | G15: ='Balance Sheet'!G21 -> 15089237 | H15: ='Balance Sheet'!H21 -> 16684258
A16: Total owners' equity | B16: ='Balance Sheet'!B32 -> 33114784 | C16: ='Balance Sheet'!C32 -> 33849635 | D16: ='Balance Sheet'!D32 -> 35303995 | E16: ='Balance Sheet'!E32 -> 35185455 | F16: ='Balance Sheet'!F32 -> 34713150 | G16: ='Balance Sheet'!G32 -> 28844374 | H16: ='Balance Sheet'!H32 -> 28783105
A17: Total assets | B17: ='Balance Sheet'!B17 -> 52857432 | C17: ='Balance Sheet'!C17 -> 51295808 | D17: ='Balance Sheet'!D17 -> 53252503 | E17: ='Balance Sheet'!E17 -> 54162371 | F17: ='Balance Sheet'!F17 -> 52653640 | G17: ='Balance Sheet'!G17 -> 47181048 | H17: ='Balance Sheet'!H17 -> 49124964
A18: Net sales (YTD) | B18: =SUM('Income Statement'!$B8:B8) -> 5292851.9 | C18: =SUM('Income Statement'!$B8:C8) -> 11008032 | D18: =SUM('Income Statement'!$B8:D8) -> 17799158 | E18: =SUM('Income Statement'!$B8:E8) -> 22957197 | F18: =SUM('Income Statement'!$B8:F8) -> 29306087 | G18: =SUM('Income Statement'!$B8:G8) -> 36211835 | H18: =SUM('Income Statement'!$B8:H8) -> 41709630
A19: COGS (YTD) | B19: =-SUM('Income Statement'!$B12:B12) -> 1219631.7 | C19: =-SUM('Income Statement'!$B12:C12) -> 2392154.6 | D19: =-SUM('Income Statement'!$B12:D12) -> 3545436 | E19: =-SUM('Income Statement'!$B12:E12) -> 4633985.1 | F19: =-SUM('Income Statement'!$B12:F12) -> 5842316.5 | G19: =-SUM('Income Statement'!$B12:G12) -> 7001517.4 | H19: =-SUM('Income Statement'!$B12:H12) -> 8155491.3
A20: Gross profit (YTD) | B20: =SUM('Income Statement'!$B13:B13) -> 4073220.2 | C20: =SUM('Income Statement'!$B13:C13) -> 8615877.3 | D20: =SUM('Income Statement'!$B13:D13) -> 14253722 | E20: =SUM('Income Statement'!$B13:E13) -> 18323211 | F20: =SUM('Income Statement'!$B13:F13) -> 23463770 | G20: =SUM('Income Statement'!$B13:G13) -> 29210318 | H20: =SUM('Income Statement'!$B13:H13) -> 33554139
A21: Operating profit (YTD) | B21: =SUM('Income Statement'!$B27:B27) -> 68506.113 | C21: =SUM('Income Statement'!$B27:C27) -> 447773.8 | D21: =SUM('Income Statement'!$B27:D27) -> 2227527.9 | E21: =SUM('Income Statement'!$B27:E27) -> 2016776 | F21: =SUM('Income Statement'!$B27:F27) -> 2718657.1 | G21: =SUM('Income Statement'!$B27:G27) -> 4562962.5 | H21: =SUM('Income Statement'!$B27:H27) -> 4356663
A22: Finance costs (YTD) | B22: =SUM('Income Statement'!$B31:B31) -> -15169.964 | C22: =SUM('Income Statement'!$B31:C31) -> -31390.474 | D22: =SUM('Income Statement'!$B31:D31) -> -50424.767 | E22: =SUM('Income Statement'!$B31:E31) -> -70337.479 | F22: =SUM('Income Statement'!$B31:F31) -> -103681.55 | G22: =SUM('Income Statement'!$B31:G31) -> -140404.74 | H22: =SUM('Income Statement'!$B31:H31) -> -161010.66
A23: Net profit (YTD) | B23: =SUM('Income Statement'!$B34:B34) -> 154839.57 | C23: =SUM('Income Statement'!$B34:C34) -> 621878.84 | D23: =SUM('Income Statement'!$B34:D34) -> 1846631.7 | E23: =SUM('Income Statement'!$B34:E34) -> 1679039.4 | F23: =SUM('Income Statement'!$B34:F34) -> 2316036.3 | G23: =SUM('Income Statement'!$B34:G34) -> 3608848 | H23: =SUM('Income Statement'!$B34:H34) -> 3417018.7
A25: Ratio | B25: =B6 -> 45777 | C25: =C6 -> 45808 | D25: =D6 -> 45838 | E25: =E6 -> 45869 | F25: =F6 -> 45900 | G25: =G6 -> 45930 | H25: =H6 -> 45961 | I25: Rating (latest) | J25: Remark (latest) | K25: Basis / note
A26: Liquidity – Current Ratio | B26: =IF(B11=0,"N/A",B10/B11) -> 2.9589173 | C26: =IF(C11=0,"N/A",C10/C11) -> 3.4666921 | D26: =IF(D11=0,"N/A",D10/D11) -> 3.2884832 | E26: =IF(E11=0,"N/A",E10/E11) -> 3.4851647 | F26: =IF(F11=0,"N/A",F10/F11) -> 3.3205131 | G26: =IF(G11=0,"N/A",G10/G11) -> 2.8375318 | H26: =IF(H11=0,"N/A",H10/H11) -> 2.7021587 | I26: =IF(ISNUMBER(H26),IF(H26<$B38,$D38,IF(H26<=$C38,$E38,$F38)),"N/A") -> Caution | J26: =IF(ISNUMBER(H26),IF(H26<$B38,$G38,IF(H26<=$C38,$H38,$I38)),"N/A") -> Average | K26: Current assets / current liabilities
A27: Liquidity – Quick Ratio | B27: =IF(B11=0,"N/A",(B12+B13)/B11) -> 2.7829309 | C27: =IF(C11=0,"N/A",(C12+C13)/C11) -> 3.2432046 | D27: =IF(D11=0,"N/A",(D12+D13)/D11) -> 3.1020487 | E27: =IF(E11=0,"N/A",(E12+E13)/E11) -> 3.2503392 | F27: =IF(F11=0,"N/A",(F12+F13)/F11) -> 3.0898955 | G27: =IF(G11=0,"N/A",(G12+G13)/G11) -> 2.6161559 | H27: =IF(H11=0,"N/A",(H12+H13)/H11) -> 2.5052555 | I27: =IF(ISNUMBER(H27),IF(H27<$B39,$D39,IF(H27<=$C39,$E39,$F39)),"N/A") -> Caution | J27: =IF(ISNUMBER(H27),IF(H27<$B39,$G39,IF(H27<=$C39,$H39,$I39)),"N/A") -> Average | K27: (Cash & investments + receivables) / current liabilities
A28: Solvency – Debt-to-Equity | B28: =IF(B16=0,"N/A",B15/B16) -> 0.49171628 | C28: =IF(C16=0,"N/A",C15/C16) -> 0.39827215 | D28: =IF(D16=0,"N/A",D15/D16) -> 0.42039593 | E28: =IF(E16=0,"N/A",E15/E16) -> 0.4052849 | F28: =IF(F16=0,"N/A",F15/F16) -> 0.41750294 | G28: =IF(G16=0,"N/A",G15/G16) -> 0.52312585 | H28: =IF(H16=0,"N/A",H15/H16) -> 0.57965456 | I28: =IF(ISNUMBER(H28),IF(H28<$B40,$D40,IF(H28<=$C40,$E40,$F40)),"N/A") -> Balanced | J28: =IF(ISNUMBER(H28),IF(H28<$B40,$G40,IF(H28<=$C40,$H40,$I40)),"N/A") -> Average | K28: Financial liabilities / equity (all debt is classed current in the COA)
A29: Solvency – Interest Coverage | B29: =IF(B22=0,"N/A",B21/ABS(B22)) -> 4.5159048 | C29: =IF(C22=0,"N/A",C21/ABS(C22)) -> 14.26464 | D29: =IF(D22=0,"N/A",D21/ABS(D22)) -> 44.175274 | E29: =IF(E22=0,"N/A",E21/ABS(E22)) -> 28.67285 | F29: =IF(F22=0,"N/A",F21/ABS(F22)) -> 26.221223 | G29: =IF(G22=0,"N/A",G21/ABS(G22)) -> 32.498637 | H29: =IF(H22=0,"N/A",H21/ABS(H22)) -> 27.058228 | I29: =IF(ISNUMBER(H29),IF(H29<$B41,$D41,IF(H29<=$C41,$E41,$F41)),"N/A") -> Excellent | J29: =IF(ISNUMBER(H29),IF(H29<$B41,$G41,IF(H29<=$C41,$H41,$I41)),"N/A") -> Excellent | K29: Operating profit / finance costs
A30: Efficiency – Days Sales Outstanding | B30: =IF(B18=0,"N/A",B13/B18*B8) -> 151.29919 | C30: =IF(C18=0,"N/A",C13/C18*C8) -> 139.61358 | D30: =IF(D18=0,"N/A",D13/D18*D8) -> 139.96424 | E30: =IF(E18=0,"N/A",E13/E18*E8) -> 149.82259 | F30: =IF(F18=0,"N/A",F13/F18*F8) -> 135.75572 | G30: =IF(G18=0,"N/A",G13/G18*G8) -> 137.24318 | H30: =IF(H18=0,"N/A",H13/H18*H8) -> 144.70413 | I30: =IF(ISNUMBER(H30),IF(H30<$B42,$D42,IF(H30<=$C42,$E42,$F42)),"N/A") -> Poor | J30: =IF(ISNUMBER(H30),IF(H30<$B42,$G42,IF(H30<=$C42,$H42,$I42)),"N/A") -> Bad | K30: Receivables / net sales x days elapsed
A31: Efficiency – Asset Turnover | B31: =IF(B17=0,"N/A",B18*B9/B17) -> 1.2016139 | C31: =IF(C17=0,"N/A",C18*C9/C17) -> 1.2875943 | D31: =IF(D17=0,"N/A",D18*D9/D17) -> 1.3369631 | E31: =IF(E17=0,"N/A",E18*E9/E17) -> 1.2715763 | F31: =IF(F17=0,"N/A",F18*F9/F17) -> 1.3357976 | G31: =IF(G17=0,"N/A",G18*G9/G17) -> 1.5350161 | H31: =IF(H17=0,"N/A",H18*H9/H17) -> 1.4555171 | I31: =IF(ISNUMBER(H31),IF(H31<$B43,$D43,IF(H31<=$C43,$E43,$F43)),"N/A") -> Average | J31: =IF(ISNUMBER(H31),IF(H31<$B43,$G43,IF(H31<=$C43,$H43,$I43)),"N/A") -> Average | K31: Annualized net sales / total assets
A32: Profitability – Gross Profit Margin | B32: =IF(B18=0,"N/A",B20/B18) -> 0.76957004 | C32: =IF(C18=0,"N/A",C20/C18) -> 0.78269007 | D32: =IF(D18=0,"N/A",D20/D18) -> 0.80080878 | E32: =IF(E18=0,"N/A",E20/E18) -> 0.79814674 | F32: =IF(F18=0,"N/A",F20/F18) -> 0.80064494 | G32: =IF(G18=0,"N/A",G20/G18) -> 0.80665113 | H32: =IF(H18=0,"N/A",H20/H18) -> 0.80446982 | I32: =IF(ISNUMBER(H32),IF(H32<$B44,$D44,IF(H32<=$C44,$E44,$F44)),"N/A") -> Excellent | J32: =IF(ISNUMBER(H32),IF(H32<$B44,$G44,IF(H32<=$C44,$H44,$I44)),"N/A") -> Excellent | K32: (Net sales – COGS) / net sales
A33: Profitability – Return on Assets | B33: =IF(B17=0,"N/A",B23*B9/B17) -> 0.035152575 | C33: =IF(C17=0,"N/A",C23*C9/C17) -> 0.072740311 | D33: =IF(D17=0,"N/A",D23*D9/D17) -> 0.1387076 | E33: =IF(E17=0,"N/A",E23*E9/E17) -> 0.093000325 | F33: =IF(F17=0,"N/A",F23*F9/F17) -> 0.105567 | G33: =IF(G17=0,"N/A",G23*G9/G17) -> 0.15297871 | H33: =IF(H17=0,"N/A",H23*H9/H17) -> 0.11924174 | I33: =IF(ISNUMBER(H33),IF(H33<$B45,$D45,IF(H33<=$C45,$E45,$F45)),"N/A") -> Good | J33: =IF(ISNUMBER(H33),IF(H33<$B45,$G45,IF(H33<=$C45,$H45,$I45)),"N/A") -> Good | K33: Annualized net profit / total assets
A34: Profitability – Return on Equity | B34: =IF(B16=0,"N/A",B23*B9/B16) -> 0.056110131 | C34: =IF(C16=0,"N/A",C23*C9/C16) -> 0.11023082 | D34: =IF(D16=0,"N/A",D23*D9/D16) -> 0.20922637 | E34: =IF(E16=0,"N/A",E23*E9/E16) -> 0.1431591 | F34: =IF(F16=0,"N/A",F23*F9/F16) -> 0.16012626 | G34: =IF(G16=0,"N/A",G23*G9/G16) -> 0.2502289 | H34: =IF(H16=0,"N/A",H23*H9/H16) -> 0.20351336 | I34: =IF(ISNUMBER(H34),IF(H34<$B46,$D46,IF(H34<=$C46,$E46,$F46)),"N/A") -> Excellent | J34: =IF(ISNUMBER(H34),IF(H34<$B46,$G46,IF(H34<=$C46,$H46,$I46)),"N/A") -> Excellent | K34: Annualized net profit / equity; ROA bands used (no ROE bands given)
A36: Rating bands (from Financial Ratios cheat sheet – inputs)
A37: Ratio | B37: Cut 1 | C37: Cut 2 | D37: Below Cut 1 | E37: Cut 1 to Cut 2 | F37: Above Cut 2 | G37: Remark: below | H37: Remark: between | I37: Remark: above
A38: =A26 -> Liquidity – Current Ratio | B38: 1.2 | C38: 2 | D38: Bad / High Risk | E38: Good / Ideal | F38: Caution | G38: Bad | H38: Good | I38: Average
A39: =A27 -> Liquidity – Quick Ratio | B39: 1 | C39: 1.5 | D39: Bad | E39: Good | F39: Caution | G39: Bad | H39: Good | I39: Average
A40: =A28 -> Solvency – Debt-to-Equity | B40: 0.5 | C40: 1.5 | D40: Conservative | E40: Balanced | F40: Risky | G40: Good | H40: Average | I40: Bad
A41: =A29 -> Solvency – Interest Coverage | B41: 1.5 | C41: 4 | D41: Danger | E41: Average | F41: Excellent | G41: Bad | H41: Average | I41: Excellent
A42: =A30 -> Efficiency – Days Sales Outstanding | B42: 30 | C42: 45 | D42: Excellent | E42: Acceptable | F42: Poor | G42: Excellent | H42: Average | I42: Bad
A43: =A31 -> Efficiency – Asset Turnover | B43: 0.5 | C43: 1.5 | D43: Weak | E43: Average | F43: Excellent | G43: Bad | H43: Average | I43: Excellent
A44: =A32 -> Profitability – Gross Profit Margin | B44: 0.2 | C44: 0.5 | D44: Weak | E44: Healthy | F44: Excellent | G44: Bad | H44: Good | I44: Excellent
...

Sheet TB Summary
A1: Trial balance summary – all companies (debit +, credit –; P&L cumulative YTD)
A2: SUMIFS of each monthly sheet's Amount by MIS Grouping
A4: Code | B4: MIS Grouping | C4: COA Account Name | D4: Type | E4: =Apr!$B$2 -> 45777 | F4: =May!$B$2 -> 45808 | G4: =Jun!$B$2 -> 45838 | H4: =Jul!$B$2 -> 45869 | I4: =Aug!$B$2 -> 45900 | J4: =Sep!$B$2 -> 45930 | K4: =Oct!$B$2 -> 45961
A5: 220 | B5: 220 PPE & Intangibles | C5: =INDEX(COA!$B$2:$B$30,MATCH(A5,COA!$A$2:$A$30,0)) -> PPE & Non-current assets | D5: =INDEX(COA!$C$2:$C$30,MATCH(A5,COA!$A$2:$A$30,0)) -> Balance Sheet | E5: =SUMIFS(Apr!$D:$D,Apr!$F:$F,$B5) -> 4108318.8 | F5: =SUMIFS(May!$D:$D,May!$F:$F,$B5) -> 4092358.3 | G5: =SUMIFS(Jun!$D:$D,Jun!$F:$F,$B5) -> 4166361.9 | H5: =SUMIFS(Jul!$D:$D,Jul!$F:$F,$B5) -> 4160953.9 | I5: =SUMIFS(Aug!$D:$D,Aug!$F:$F,$B5) -> 4265861.5 | J5: =SUMIFS(Sep!$D:$D,Sep!$F:$F,$B5) -> 4237690.7 | K5: =SUMIFS(Oct!$D:$D,Oct!$F:$F,$B5) -> 4161494.1
A6: 225 | B6: 225 Goodwill | C6: =INDEX(COA!$B$2:$B$30,MATCH(A6,COA!$A$2:$A$30,0)) -> Goodwill & Intangibles | D6: =INDEX(COA!$C$2:$C$30,MATCH(A6,COA!$A$2:$A$30,0)) -> Balance Sheet | E6: =SUMIFS(Apr!$D:$D,Apr!$F:$F,$B6) -> 83942.334 | F6: =SUMIFS(May!$D:$D,May!$F:$F,$B6) -> 82402.121 | G6: =SUMIFS(Jun!$D:$D,Jun!$F:$F,$B6) -> 80092.229 | H6: =SUMIFS(Jul!$D:$D,Jul!$F:$F,$B6) -> 76394.458 | I6: =SUMIFS(Aug!$D:$D,Aug!$F:$F,$B6) -> 72965.501 | J6: =SUMIFS(Sep!$D:$D,Sep!$F:$F,$B6) -> 70600.753 | K6: =SUMIFS(Oct!$D:$D,Oct!$F:$F,$B6) -> 67771.199
A7: 230 | B7: 230 Cash, Bank, FDs & Investments | C7: =INDEX(COA!$B$2:$B$30,MATCH(A7,COA!$A$2:$A$30,0)) -> Cash | D7: =INDEX(COA!$C$2:$C$30,MATCH(A7,COA!$A$2:$A$30,0)) -> Balance Sheet | E7: =SUMIFS(Apr!$D:$D,Apr!$F:$F,$B7) -> 18621208 | F7: =SUMIFS(May!$D:$D,May!$F:$F,$B7) -> 18528228 | G7: =SUMIFS(Jun!$D:$D,Jun!$F:$F,$B7) -> 18663213 | H7: =SUMIFS(Jul!$D:$D,Jul!$F:$F,$B7) -> 18157595 | I7: =SUMIFS(Aug!$D:$D,Aug!$F:$F,$B7) -> 18778304 | J7: =SUMIFS(Sep!$D:$D,Sep!$F:$F,$B7) -> 12318272 | K7: =SUMIFS(Oct!$D:$D,Oct!$F:$F,$B7) -> 13594797
A8: 240 | B8: 240 Other financial assets | C8: =INDEX(COA!$B$2:$B$30,MATCH(A8,COA!$A$2:$A$30,0)) -> Other Financial Assets | D8: =INDEX(COA!$C$2:$C$30,MATCH(A8,COA!$A$2:$A$30,0)) -> Balance Sheet | E8: =SUMIFS(Apr!$D:$D,Apr!$F:$F,$B8) -> 484888.92 | F8: =SUMIFS(May!$D:$D,May!$F:$F,$B8) -> 385300.57 | G8: =SUMIFS(Jun!$D:$D,Jun!$F:$F,$B8) -> 199512.99 | H8: =SUMIFS(Jul!$D:$D,Jul!$F:$F,$B8) -> 226108.44 | I8: =SUMIFS(Aug!$D:$D,Aug!$F:$F,$B8) -> 191140.7 | J8: =SUMIFS(Sep!$D:$D,Sep!$F:$F,$B8) -> 56565.475 | K8: =SUMIFS(Oct!$D:$D,Oct!$F:$F,$B8) -> -187814.82
A9: 245 | B9: 245 Other assets | C9: =INDEX(COA!$B$2:$B$30,MATCH(A9,COA!$A$2:$A$30,0)) -> Other Assets | D9: =INDEX(COA!$C$2:$C$30,MATCH(A9,COA!$A$2:$A$30,0)) -> Balance Sheet | E9: =SUMIFS(Apr!$D:$D,Apr!$F:$F,$B9) -> 1232168.9 | F9: =SUMIFS(May!$D:$D,May!$F:$F,$B9) -> 1274561.2 | G9: =SUMIFS(Jun!$D:$D,Jun!$F:$F,$B9) -> 1362766.2 | H9: =SUMIFS(Jul!$D:$D,Jul!$F:$F,$B9) -> 1787036 | I9: =SUMIFS(Aug!$D:$D,Aug!$F:$F,$B9) -> 1676810.7 | J9: =SUMIFS(Sep!$D:$D,Sep!$F:$F,$B9) -> 1599013 | K9: =SUMIFS(Oct!$D:$D,Oct!$F:$F,$B9) -> 1484902.5
A10: 250 | B10: 250 Trade receivables & Unbilled Revenue | C10: =INDEX(COA!$B$2:$B$30,MATCH(A10,COA!$A$2:$A$30,0)) -> Trade Receivables | D10: =INDEX(COA!$C$2:$C$30,MATCH(A10,COA!$A$2:$A$30,0)) -> Balance Sheet | E10: =SUMIFS(Apr!$D:$D,Apr!$F:$F,$B10) -> 26693473 | F10: =SUMIFS(May!$D:$D,May!$F:$F,$B10) -> 25194603 | G10: =SUMIFS(Jun!$D:$D,Jun!$F:$F,$B10) -> 27376325 | H10: =SUMIFS(Jul!$D:$D,Jul!$F:$F,$B10) -> 28192677 | I10: =SUMIFS(Aug!$D:$D,Aug!$F:$F,$B10) -> 26003064 | J10: =SUMIFS(Sep!$D:$D,Sep!$F:$F,$B10) -> 27157526 | K10: =SUMIFS(Oct!$D:$D,Oct!$F:$F,$B10) -> 28203532
A11: 255 | B11: 255 Income Tax & deferred tax assets | C11: =INDEX(COA!$B$2:$B$30,MATCH(A11,COA!$A$2:$A$30,0)) -> Income Tax Receivables | D11: =INDEX(COA!$C$2:$C$30,MATCH(A11,COA!$A$2:$A$30,0)) -> Balance Sheet | E11: =SUMIFS(Apr!$D:$D,Apr!$F:$F,$B11) -> 1633432.4 | F11: =SUMIFS(May!$D:$D,May!$F:$F,$B11) -> 1738354.7 | G11: =SUMIFS(Jun!$D:$D,Jun!$F:$F,$B11) -> 1404231.3 | H11: =SUMIFS(Jul!$D:$D,Jul!$F:$F,$B11) -> 1561606.6 | I11: =SUMIFS(Aug!$D:$D,Aug!$F:$F,$B11) -> 1665493.5 | J11: =SUMIFS(Sep!$D:$D,Sep!$F:$F,$B11) -> 1741381 | K11: =SUMIFS(Oct!$D:$D,Oct!$F:$F,$B11) -> 1800281.2
A12: 260 | B12: 260 Equity | C12: =INDEX(COA!$B$2:$B$30,MATCH(A12,COA!$A$2:$A$30,0)) -> Equity | D12: =INDEX(COA!$C$2:$C$30,MATCH(A12,COA!$A$2:$A$30,0)) -> Balance Sheet | E12: =SUMIFS(Apr!$D:$D,Apr!$F:$F,$B12) -> -32959944 | F12: =SUMIFS(May!$D:$D,May!$F:$F,$B12) -> -33227756 | G12: =SUMIFS(Jun!$D:$D,Jun!$F:$F,$B12) -> -33457363 | H12: =SUMIFS(Jul!$D:$D,Jul!$F:$F,$B12) -> -33506416 | I12: =SUMIFS(Aug!$D:$D,Aug!$F:$F,$B12) -> -32397114 | J12: =SUMIFS(Sep!$D:$D,Sep!$F:$F,$B12) -> -25235526 | K12: =SUMIFS(Oct!$D:$D,Oct!$F:$F,$B12) -> -25366086
A13: 270 | B13: 270 Financial liabilities | C13: =INDEX(COA!$B$2:$B$30,MATCH(A13,COA!$A$2:$A$30,0)) -> Financial Liabilities | D13: =INDEX(COA!$C$2:$C$30,MATCH(A13,COA!$A$2:$A$30,0)) -> Balance Sheet | E13: =SUMIFS(Apr!$D:$D,Apr!$F:$F,$B13) -> -16283078 | F13: =SUMIFS(May!$D:$D,May!$F:$F,$B13) -> -13481367 | G13: =SUMIFS(Jun!$D:$D,Jun!$F:$F,$B13) -> -14841656 | H13: =SUMIFS(Jul!$D:$D,Jul!$F:$F,$B13) -> -14260134 | I13: =SUMIFS(Aug!$D:$D,Aug!$F:$F,$B13) -> -14492842 | J13: =SUMIFS(Sep!$D:$D,Sep!$F:$F,$B13) -> -15089237 | K13: =SUMIFS(Oct!$D:$D,Oct!$F:$F,$B13) -> -16684258
